
Running tests...
----------------------------------------------------------------------
E...
======================================================================
ERROR [0.006s]: a6MV_tests (unittest.loader._FailedTest)
----------------------------------------------------------------------
Traceback (most recent call last):
  File "C:\Program Files\WindowsApps\PythonSoftwareFoundation.Python.3.9_3.9.3568.0_x64__qbz5n2kfra8p0\lib\unittest\case.py", line 59, in testPartExecutor
    yield
  File "C:\Program Files\WindowsApps\PythonSoftwareFoundation.Python.3.9_3.9.3568.0_x64__qbz5n2kfra8p0\lib\unittest\case.py", line 592, in run
    self._callTestMethod(testMethod)
  File "C:\Program Files\WindowsApps\PythonSoftwareFoundation.Python.3.9_3.9.3568.0_x64__qbz5n2kfra8p0\lib\unittest\case.py", line 550, in _callTestMethod
    method()
  File "C:\Program Files\WindowsApps\PythonSoftwareFoundation.Python.3.9_3.9.3568.0_x64__qbz5n2kfra8p0\lib\unittest\loader.py", line 34, in testFailure
    raise self._exception
ImportError: Failed to import test module: a6MV_tests
Traceback (most recent call last):
  File "C:\Program Files\WindowsApps\PythonSoftwareFoundation.Python.3.9_3.9.3568.0_x64__qbz5n2kfra8p0\lib\unittest\loader.py", line 154, in loadTestsFromName
    module = __import__(module_name)
  File "c:\users\moina\documents\..cpp\.f2022\cs 4800\c2c\c2c\src\unittest\python\a6MV_tests.py", line 2, in <module>
    from src.main.python.a6MV import validTime
ModuleNotFoundError: No module named 'src'


----------------------------------------------------------------------
Ran 4 tests in 0.102s

FAILED (errors=1)

Generating XML reports...
